<?xml version="1.0"?>
<robot name="my_bot" xmlns:xacro="http://www.ros.org/wiki/xacro">

  <!-- ================= 参数定义 ================= -->
  <xacro:property name="chassis_len" value="0.4" />
  <xacro:property name="chassis_width" value="0.3" />
  <xacro:property name="chassis_height" value="0.1" />
  <xacro:property name="wheel_radius" value="0.05" />
  
  <!-- 惯性矩阵宏 (物理引擎防炸关键) -->
  <xacro:macro name="box_inertia" params="m w h d">
    <inertial>
      <mass value="${m}"/>
      <inertia ixx="${m / 12.0 * (d*d + h*h)}" ixy="0.0" ixz="0.0" iyy="${m / 12.0 * (w*w + h*h)}" iyz="0.0" izz="${m / 12.0 * (w*w + d*d)}"/>
    </inertial>
  </xacro:macro>

  <!-- ================= 1. 底盘 (Base Link) ================= -->
  <link name="base_link">
    <visual>
      <geometry>
        <box size="${chassis_len} ${chassis_width} ${chassis_height}"/>
      </geometry>
      <material name="blue">
        <color rgba="0 0 0.8 1"/>
      </material>
    </visual>
    <collision>
      <geometry>
        <box size="${chassis_len} ${chassis_width} ${chassis_height}"/>
      </geometry>
    </collision>
    <xacro:box_inertia m="5.0" w="${chassis_len}" h="${chassis_height}" d="${chassis_width}"/>
  </link>

  <!-- ================= 2. 轮子 (Diff Drive) ================= -->
  <!-- 左轮 -->
  <link name="left_wheel">
    <visual>
      <geometry><cylinder radius="${wheel_radius}" length="0.04"/></geometry>
      <material name="black"><color rgba="0 0 0 1"/></material>
    </visual>
    <collision>
      <geometry><cylinder radius="${wheel_radius}" length="0.04"/></geometry>
    </collision>
    <inertial>
      <mass value="1.0"/>
      <inertia ixx="0.1" ixy="0" ixz="0" iyy="0.1" iyz="0" izz="0.1"/>
    </inertial>
  </link>

  <joint name="left_wheel_joint" type="continuous">
    <parent link="base_link"/>
    <child link="left_wheel"/>
    <origin xyz="0 0.17 -0.05" rpy="-1.5707 0 0"/>
    <axis xyz="0 0 1"/>
  </joint>

  <!-- 右轮 -->
  <link name="right_wheel">
    <visual>
      <geometry><cylinder radius="${wheel_radius}" length="0.04"/></geometry>
      <material name="black"><color rgba="0 0 0 1"/></material>
    </visual>
    <collision>
      <geometry><cylinder radius="${wheel_radius}" length="0.04"/></geometry>
    </collision>
    <inertial>
      <mass value="1.0"/>
      <inertia ixx="0.1" ixy="0" ixz="0" iyy="0.1" iyz="0" izz="0.1"/>
    </inertial>
  </link>

  <joint name="right_wheel_joint" type="continuous">
    <parent link="base_link"/>
    <child link="right_wheel"/>
    <origin xyz="0 -0.17 -0.05" rpy="-1.5707 0 0"/>
    <axis xyz="0 0 1"/>
  </joint>

  <!-- 万向轮 (支撑轮) -->
  <link name="caster_wheel">
    <visual>
      <geometry><sphere radius="0.05"/></geometry>
    </visual>
    <collision>
      <geometry><sphere radius="0.05"/></geometry>
      <surface>
        <friction>
          <ode><mu>0.0</mu><mu2>0.0</mu2></ode> <!-- 摩擦力设为0，防止卡住 -->
        </friction>
      </surface>
    </collision>
    <inertial>
      <mass value="0.5"/>
      <inertia ixx="0.01" ixy="0" ixz="0" iyy="0.01" iyz="0" izz="0.01"/>
    </inertial>
  </link>

  <joint name="caster_joint" type="fixed">
    <parent link="base_link"/>
    <child link="caster_wheel"/>
    <origin xyz="-0.15 0 -0.05"/>
  </joint>

  <!-- ================= 3. 传感器: 3D LiDAR (关键!) ================= -->
  <link name="velodyne">
    <visual>
      <geometry><cylinder radius="0.05" length="0.07"/></geometry>
      <material name="orange"><color rgba="1 0.5 0 1"/></material>
    </visual>
    <inertial>
      <mass value="0.1"/>
      <inertia ixx="0.001" ixy="0" ixz="0" iyy="0.001" iyz="0" izz="0.001"/>
    </inertial>
  </link>

  <joint name="velodyne_joint" type="fixed">
    <parent link="base_link"/>
    <child link="velodyne"/>
    <origin xyz="0 0 0.085" rpy="0 0 0"/>
  </joint>

  <!-- Gazebo LiDAR 插件 -->
  <gazebo reference="velodyne">
    <sensor type="ray" name="velodyne-VLP16">
      <pose>0 0 0 0 0 0</pose>
      <visualize>false</visualize>
      <update_rate>10</update_rate>
      <ray>
        <scan>
          <horizontal>
            <samples>440</samples> <!-- 水平分辨率 -->
            <resolution>1</resolution>
            <min_angle>-3.14159</min_angle>
            <max_angle>3.14159</max_angle>
          </horizontal>
          <vertical>
            <samples>16</samples> <!-- 垂直16线，这就叫3D雷达 -->
            <resolution>1</resolution>
            <min_angle>-0.26</min_angle> <!-- -15度 -->
            <max_angle>0.26</max_angle>  <!-- +15度 -->
          </vertical>
        </scan>
        <range>
          <min>0.3</min>
          <max>100.0</max>
          <resolution>0.001</resolution>
        </range>
        <noise>
          <type>gaussian</type>
          <mean>0.0</mean>
          <stddev>0.01</stddev>
        </noise>
      </ray>
      <!-- 重点：加载 Velodyne 插件，输出 PointCloud2 -->
      <plugin name="gazebo_ros_laser_controller" filename="libgazebo_ros_velodyne_laser.so">
        <topicName>/velodyne_points</topicName> <!-- CMU算法需要的话题 -->
        <frameName>velodyne</frameName>
        <min_range>0.9</min_range>
        <max_range>130.0</max_range>
        <gaussianNoise>0.008</gaussianNoise>
      </plugin>
    </sensor>
  </gazebo>

  <!-- ================= 4. 传感器: IMU (关键!) ================= -->
  <link name="imu_link"/>
  <joint name="imu_joint" type="fixed">
    <parent link="base_link"/>
    <child link="imu_link"/>
    <origin xyz="0 0 0" rpy="0 0 0"/>
  </joint>

  <gazebo reference="imu_link">
    <gravity>true</gravity>
    <sensor name="imu_sensor" type="imu">
      <always_on>true</always_on>
      <update_rate>500</update_rate>
      <visualize>true</visualize>
      <topic>__default_topic__</topic>
      <plugin filename="libgazebo_ros_imu_sensor.so" name="imu_plugin">
        <topicName>/imu/data</topicName>
        <bodyName>imu_link</bodyName>
        <updateRateHZ>500.0</updateRateHZ>
        <gaussianNoise>0.0</gaussianNoise>
        <xyzOffset>0 0 0</xyzOffset>
        <rpyOffset>0 0 0</rpyOffset>
        <frameName>imu_link</frameName>
      </plugin>
    </sensor>
  </gazebo>

  <!-- ================= 5. 运动控制插件 (Diff Drive) ================= -->
  <gazebo>
    <plugin name="differential_drive_controller" filename="libgazebo_ros_diff_drive.so">
      <updateRate>50</updateRate>
      <leftJoint>left_wheel_joint</leftJoint>
      <rightJoint>right_wheel_joint</rightJoint>
      <wheelSeparation>0.34</wheelSeparation>
      <wheelDiameter>0.1</wheelDiameter>
      <wheelAcceleration>1.0</wheelAcceleration>
      <wheelTorque>20</wheelTorque>
      <commandTopic>cmd_vel</commandTopic> <!-- Local Planner 只需要发给这里 -->
      <odometryTopic>odom</odometryTopic>
      <odometryFrame>odom</odometryFrame>
      <robotBaseFrame>base_link</robotBaseFrame>
      <publishWheelTF>true</publishWheelTF>
      <publishOdomTF>true</publishOdomTF> <!-- 方便调试，如果是跑 LIO-SAM 可以设为 false -->
      <publishWheelJointState>true</publishWheelJointState>
    </plugin>
  </gazebo>

</robot>
